2023-11-27 09:32:27,629 ERROR: Exception on /user/kristofero [GET] [in C:\Users\STUDENT.LAPTOP-67\AppData\Local\Programs\Python\Python312\Lib\site-packages\flask\app.py:825]
Traceback (most recent call last):
  File "C:\Users\STUDENT.LAPTOP-67\AppData\Local\Programs\Python\Python312\Lib\site-packages\sqlalchemy\engine\base.py", line 1969, in _exec_single_context
    self.dialect.do_execute(
  File "C:\Users\STUDENT.LAPTOP-67\AppData\Local\Programs\Python\Python312\Lib\site-packages\sqlalchemy\engine\default.py", line 922, in do_execute
    cursor.execute(statement, parameters)
sqlite3.OperationalError: no such table: followers

The above exception was the direct cause of the following exception:

Traceback (most recent call last):
  File "C:\Users\STUDENT.LAPTOP-67\AppData\Local\Programs\Python\Python312\Lib\site-packages\flask\app.py", line 1455, in wsgi_app
    response = self.full_dispatch_request()
               ^^^^^^^^^^^^^^^^^^^^^^^^^^^^
  File "C:\Users\STUDENT.LAPTOP-67\AppData\Local\Programs\Python\Python312\Lib\site-packages\flask\app.py", line 869, in full_dispatch_request
    rv = self.handle_user_exception(e)
         ^^^^^^^^^^^^^^^^^^^^^^^^^^^^^
  File "C:\Users\STUDENT.LAPTOP-67\AppData\Local\Programs\Python\Python312\Lib\site-packages\flask\app.py", line 867, in full_dispatch_request
    rv = self.dispatch_request()
         ^^^^^^^^^^^^^^^^^^^^^^^
  File "C:\Users\STUDENT.LAPTOP-67\AppData\Local\Programs\Python\Python312\Lib\site-packages\flask\app.py", line 852, in dispatch_request
    return self.ensure_sync(self.view_functions[rule.endpoint])(**view_args)
           ^^^^^^^^^^^^^^^^^^^^^^^^^^^^^^^^^^^^^^^^^^^^^^^^^^^^^^^^^^^^^^^^^
  File "C:\Users\STUDENT.LAPTOP-67\AppData\Local\Programs\Python\Python312\Lib\site-packages\flask_login\utils.py", line 290, in decorated_view
    return current_app.ensure_sync(func)(*args, **kwargs)
           ^^^^^^^^^^^^^^^^^^^^^^^^^^^^^^^^^^^^^^^^^^^^^^
  File "C:\Users\STUDENT.LAPTOP-67\Desktop\globodain\microblog\app\routes.py", line 107, in user
    return render_template('user.html', user=user, posts=posts.items,
           ^^^^^^^^^^^^^^^^^^^^^^^^^^^^^^^^^^^^^^^^^^^^^^^^^^^^^^^^^^
  File "C:\Users\STUDENT.LAPTOP-67\AppData\Local\Programs\Python\Python312\Lib\site-packages\flask\templating.py", line 152, in render_template
    return _render(app, template, context)
           ^^^^^^^^^^^^^^^^^^^^^^^^^^^^^^^
  File "C:\Users\STUDENT.LAPTOP-67\AppData\Local\Programs\Python\Python312\Lib\site-packages\flask\templating.py", line 133, in _render
    rv = template.render(context)
         ^^^^^^^^^^^^^^^^^^^^^^^^
  File "C:\Users\STUDENT.LAPTOP-67\AppData\Local\Programs\Python\Python312\Lib\site-packages\jinja2\environment.py", line 1301, in render
    self.environment.handle_exception()
  File "C:\Users\STUDENT.LAPTOP-67\AppData\Local\Programs\Python\Python312\Lib\site-packages\jinja2\environment.py", line 936, in handle_exception
    raise rewrite_traceback_stack(source=source)
  File "C:\Users\STUDENT.LAPTOP-67\Desktop\globodain\microblog\app\templates\user.html", line 2, in top-level template code
    {% extends "base.html" %}
  File "C:\Users\STUDENT.LAPTOP-67\Desktop\globodain\microblog\app\templates\base.html", line 32, in top-level template code
    {% block content %}{% endblock %}
    ^^^^^^^^^^^^^^^^^^^^^^^^^
  File "C:\Users\STUDENT.LAPTOP-67\Desktop\globodain\microblog\app\templates\user.html", line 12, in block 'content'
    <p>{{ user.followers.count() }} followers, {{ user.followed.count() }} following.</p>
    ^^^^^^^^^^^^^^^^^^^^^^^^^
  File "C:\Users\STUDENT.LAPTOP-67\AppData\Local\Programs\Python\Python312\Lib\site-packages\sqlalchemy\orm\dynamic.py", line 198, in count
    return self._generate(sess).count()
           ^^^^^^^^^^^^^^^^^^^^^^^^^^^^
  File "C:\Users\STUDENT.LAPTOP-67\AppData\Local\Programs\Python\Python312\Lib\site-packages\sqlalchemy\orm\query.py", line 3132, in count
    self._legacy_from_self(col).enable_eagerloads(False).scalar()
  File "C:\Users\STUDENT.LAPTOP-67\AppData\Local\Programs\Python\Python312\Lib\site-packages\sqlalchemy\orm\query.py", line 2825, in scalar
    ret = self.one()
          ^^^^^^^^^^
  File "C:\Users\STUDENT.LAPTOP-67\AppData\Local\Programs\Python\Python312\Lib\site-packages\sqlalchemy\orm\query.py", line 2798, in one
    return self._iter().one()  # type: ignore
           ^^^^^^^^^^^^
  File "C:\Users\STUDENT.LAPTOP-67\AppData\Local\Programs\Python\Python312\Lib\site-packages\sqlalchemy\orm\query.py", line 2847, in _iter
    result: Union[ScalarResult[_T], Result[_T]] = self.session.execute(
                                                  ^^^^^^^^^^^^^^^^^^^^^
  File "C:\Users\STUDENT.LAPTOP-67\AppData\Local\Programs\Python\Python312\Lib\site-packages\sqlalchemy\orm\session.py", line 2308, in execute
    return self._execute_internal(
           ^^^^^^^^^^^^^^^^^^^^^^^
  File "C:\Users\STUDENT.LAPTOP-67\AppData\Local\Programs\Python\Python312\Lib\site-packages\sqlalchemy\orm\session.py", line 2190, in _execute_internal
    result: Result[Any] = compile_state_cls.orm_execute_statement(
                          ^^^^^^^^^^^^^^^^^^^^^^^^^^^^^^^^^^^^^^^^
  File "C:\Users\STUDENT.LAPTOP-67\AppData\Local\Programs\Python\Python312\Lib\site-packages\sqlalchemy\orm\context.py", line 293, in orm_execute_statement
    result = conn.execute(
             ^^^^^^^^^^^^^
  File "C:\Users\STUDENT.LAPTOP-67\AppData\Local\Programs\Python\Python312\Lib\site-packages\sqlalchemy\engine\base.py", line 1416, in execute
    return meth(
           ^^^^^
  File "C:\Users\STUDENT.LAPTOP-67\AppData\Local\Programs\Python\Python312\Lib\site-packages\sqlalchemy\sql\elements.py", line 516, in _execute_on_connection
    return connection._execute_clauseelement(
           ^^^^^^^^^^^^^^^^^^^^^^^^^^^^^^^^^^
  File "C:\Users\STUDENT.LAPTOP-67\AppData\Local\Programs\Python\Python312\Lib\site-packages\sqlalchemy\engine\base.py", line 1639, in _execute_clauseelement
    ret = self._execute_context(
          ^^^^^^^^^^^^^^^^^^^^^^
  File "C:\Users\STUDENT.LAPTOP-67\AppData\Local\Programs\Python\Python312\Lib\site-packages\sqlalchemy\engine\base.py", line 1848, in _execute_context
    return self._exec_single_context(
           ^^^^^^^^^^^^^^^^^^^^^^^^^^
  File "C:\Users\STUDENT.LAPTOP-67\AppData\Local\Programs\Python\Python312\Lib\site-packages\sqlalchemy\engine\base.py", line 1988, in _exec_single_context
    self._handle_dbapi_exception(
  File "C:\Users\STUDENT.LAPTOP-67\AppData\Local\Programs\Python\Python312\Lib\site-packages\sqlalchemy\engine\base.py", line 2343, in _handle_dbapi_exception
    raise sqlalchemy_exception.with_traceback(exc_info[2]) from e
  File "C:\Users\STUDENT.LAPTOP-67\AppData\Local\Programs\Python\Python312\Lib\site-packages\sqlalchemy\engine\base.py", line 1969, in _exec_single_context
    self.dialect.do_execute(
  File "C:\Users\STUDENT.LAPTOP-67\AppData\Local\Programs\Python\Python312\Lib\site-packages\sqlalchemy\engine\default.py", line 922, in do_execute
    cursor.execute(statement, parameters)
sqlalchemy.exc.OperationalError: (sqlite3.OperationalError) no such table: followers
[SQL: SELECT count(*) AS count_1 
FROM (SELECT user.id AS user_id, user.username AS user_username, user.email AS user_email, user.password_hash AS user_password_hash, user.about_me AS user_about_me, user.last_seen AS user_last_seen 
FROM user, followers 
WHERE followers.followed_id = ? AND followers.follower_id = user.id) AS anon_1]
[parameters: (3,)]
(Background on this error at: https://sqlalche.me/e/20/e3q8)
